[02/Sep/2016 09:56:36] "GET /tyreport/ HTTP/1.1" 302 0
[02/Sep/2016 09:56:36] "GET /tyblog/tyreport/ HTTP/1.1" 200 378734
Performing system checks...

System check identified no issues (0 silenced).
September 02, 2016 - 09:56:26
Django version 1.9.8, using settings 'myweb.settings'
Starting development server at http://0.0.0.0:8000/
Quit the server with CONTROL-C.
[02/Sep/2016 10:07:54] "GET /admin/ HTTP/1.1" 302 0
[02/Sep/2016 10:07:54] "GET /admin/login/?next=/admin/ HTTP/1.1" 200 1683
[02/Sep/2016 10:07:54] "GET /static/admin/css/base.css HTTP/1.1" 200 15897
[02/Sep/2016 10:07:54] "GET /static/admin/css/fonts.css HTTP/1.1" 200 423
[02/Sep/2016 10:07:54] "GET /static/admin/css/login.css HTTP/1.1" 200 1203
[02/Sep/2016 10:07:54] "GET /static/admin/fonts/Roboto-Light-webfont.woff HTTP/1.1" 200 81348
[02/Sep/2016 10:07:54] "GET /static/admin/fonts/Roboto-Regular-webfont.woff HTTP/1.1" 200 80304
[02/Sep/2016 10:07:56] "POST /admin/login/?next=/admin/ HTTP/1.1" 302 0
[02/Sep/2016 10:07:56] "GET /admin/ HTTP/1.1" 200 3414
[02/Sep/2016 10:07:56] "GET /static/admin/css/dashboard.css HTTP/1.1" 200 434
[02/Sep/2016 10:07:56] "GET /static/admin/fonts/Roboto-Bold-webfont.woff HTTP/1.1" 200 82564
[02/Sep/2016 10:07:56] "GET /static/admin/img/icon-addlink.svg HTTP/1.1" 200 331
[02/Sep/2016 10:07:56] "GET /static/admin/img/icon-changelink.svg HTTP/1.1" 200 380
Internal Server Error: /admin/intest/ints/
Traceback (most recent call last):
  File "/root/.pyenv/versions/3.5.1/lib/python3.5/site-packages/django/db/backends/utils.py", line 64, in execute
    return self.cursor.execute(sql, params)
  File "/root/.pyenv/versions/3.5.1/lib/python3.5/site-packages/django/db/backends/mysql/base.py", line 112, in execute
    return self.cursor.execute(query, args)
  File "/root/.pyenv/versions/3.5.1/lib/python3.5/site-packages/pymysql/cursors.py", line 161, in execute
    result = self._query(query)
  File "/root/.pyenv/versions/3.5.1/lib/python3.5/site-packages/pymysql/cursors.py", line 317, in _query
    conn.query(q)
  File "/root/.pyenv/versions/3.5.1/lib/python3.5/site-packages/pymysql/connections.py", line 837, in query
    self._affected_rows = self._read_query_result(unbuffered=unbuffered)
  File "/root/.pyenv/versions/3.5.1/lib/python3.5/site-packages/pymysql/connections.py", line 1021, in _read_query_result
    result.read()
  File "/root/.pyenv/versions/3.5.1/lib/python3.5/site-packages/pymysql/connections.py", line 1304, in read
    first_packet = self.connection._read_packet()
  File "/root/.pyenv/versions/3.5.1/lib/python3.5/site-packages/pymysql/connections.py", line 983, in _read_packet
    packet.check_error()
  File "/root/.pyenv/versions/3.5.1/lib/python3.5/site-packages/pymysql/connections.py", line 395, in check_error
    err.raise_mysql_exception(self._data)
  File "/root/.pyenv/versions/3.5.1/lib/python3.5/site-packages/pymysql/err.py", line 120, in raise_mysql_exception
    _check_mysql_exception(errinfo)
  File "/root/.pyenv/versions/3.5.1/lib/python3.5/site-packages/pymysql/err.py", line 112, in _check_mysql_exception
    raise errorclass(errno, errorvalue)
pymysql.err.ProgrammingError: (1146, "Table 'intest.intest_ints' doesn't exist")

The above exception was the direct cause of the following exception:

Traceback (most recent call last):
  File "/root/.pyenv/versions/3.5.1/lib/python3.5/site-packages/django/core/handlers/base.py", line 149, in get_response
    response = self.process_exception_by_middleware(e, request)
  File "/root/.pyenv/versions/3.5.1/lib/python3.5/site-packages/django/core/handlers/base.py", line 147, in get_response
    response = wrapped_callback(request, *callback_args, **callback_kwargs)
  File "/root/.pyenv/versions/3.5.1/lib/python3.5/site-packages/django/contrib/admin/options.py", line 541, in wrapper
    return self.admin_site.admin_view(view)(*args, **kwargs)
  File "/root/.pyenv/versions/3.5.1/lib/python3.5/site-packages/django/utils/decorators.py", line 149, in _wrapped_view
    response = view_func(request, *args, **kwargs)
  File "/root/.pyenv/versions/3.5.1/lib/python3.5/site-packages/django/views/decorators/cache.py", line 57, in _wrapped_view_func
    response = view_func(request, *args, **kwargs)
  File "/root/.pyenv/versions/3.5.1/lib/python3.5/site-packages/django/contrib/admin/sites.py", line 244, in inner
    return view(request, *args, **kwargs)
  File "/root/.pyenv/versions/3.5.1/lib/python3.5/site-packages/django/utils/decorators.py", line 67, in _wrapper
    return bound_func(*args, **kwargs)
  File "/root/.pyenv/versions/3.5.1/lib/python3.5/site-packages/django/utils/decorators.py", line 149, in _wrapped_view
    response = view_func(request, *args, **kwargs)
  File "/root/.pyenv/versions/3.5.1/lib/python3.5/site-packages/django/utils/decorators.py", line 63, in bound_func
    return func.__get__(self, type(self))(*args2, **kwargs2)
  File "/root/.pyenv/versions/3.5.1/lib/python3.5/site-packages/django/contrib/admin/options.py", line 1470, in changelist_view
    self.list_max_show_all, self.list_editable, self)
  File "/root/.pyenv/versions/3.5.1/lib/python3.5/site-packages/django/contrib/admin/views/main.py", line 79, in __init__
    self.get_results(request)
  File "/root/.pyenv/versions/3.5.1/lib/python3.5/site-packages/django/contrib/admin/views/main.py", line 174, in get_results
    result_count = paginator.count
  File "/root/.pyenv/versions/3.5.1/lib/python3.5/site-packages/django/core/paginator.py", line 72, in _get_count
    self._count = self.object_list.count()
  File "/root/.pyenv/versions/3.5.1/lib/python3.5/site-packages/django/db/models/query.py", line 371, in count
    return self.query.get_count(using=self.db)
  File "/root/.pyenv/versions/3.5.1/lib/python3.5/site-packages/django/db/models/sql/query.py", line 483, in get_count
    number = obj.get_aggregation(using, ['__count'])['__count']
  File "/root/.pyenv/versions/3.5.1/lib/python3.5/site-packages/django/db/models/sql/query.py", line 464, in get_aggregation
    result = compiler.execute_sql(SINGLE)
  File "/root/.pyenv/versions/3.5.1/lib/python3.5/site-packages/django/db/models/sql/compiler.py", line 848, in execute_sql
    cursor.execute(sql, params)
  File "/root/.pyenv/versions/3.5.1/lib/python3.5/site-packages/django/db/backends/utils.py", line 79, in execute
    return super(CursorDebugWrapper, self).execute(sql, params)
  File "/root/.pyenv/versions/3.5.1/lib/python3.5/site-packages/django/db/backends/utils.py", line 64, in execute
    return self.cursor.execute(sql, params)
  File "/root/.pyenv/versions/3.5.1/lib/python3.5/site-packages/django/db/utils.py", line 95, in __exit__
    six.reraise(dj_exc_type, dj_exc_value, traceback)
  File "/root/.pyenv/versions/3.5.1/lib/python3.5/site-packages/django/utils/six.py", line 685, in reraise
    raise value.with_traceback(tb)
  File "/root/.pyenv/versions/3.5.1/lib/python3.5/site-packages/django/db/backends/utils.py", line 64, in execute
    return self.cursor.execute(sql, params)
  File "/root/.pyenv/versions/3.5.1/lib/python3.5/site-packages/django/db/backends/mysql/base.py", line 112, in execute
    return self.cursor.execute(query, args)
  File "/root/.pyenv/versions/3.5.1/lib/python3.5/site-packages/pymysql/cursors.py", line 161, in execute
    result = self._query(query)
  File "/root/.pyenv/versions/3.5.1/lib/python3.5/site-packages/pymysql/cursors.py", line 317, in _query
    conn.query(q)
  File "/root/.pyenv/versions/3.5.1/lib/python3.5/site-packages/pymysql/connections.py", line 837, in query
    self._affected_rows = self._read_query_result(unbuffered=unbuffered)
  File "/root/.pyenv/versions/3.5.1/lib/python3.5/site-packages/pymysql/connections.py", line 1021, in _read_query_result
    result.read()
  File "/root/.pyenv/versions/3.5.1/lib/python3.5/site-packages/pymysql/connections.py", line 1304, in read
    first_packet = self.connection._read_packet()
  File "/root/.pyenv/versions/3.5.1/lib/python3.5/site-packages/pymysql/connections.py", line 983, in _read_packet
    packet.check_error()
  File "/root/.pyenv/versions/3.5.1/lib/python3.5/site-packages/pymysql/connections.py", line 395, in check_error
    err.raise_mysql_exception(self._data)
  File "/root/.pyenv/versions/3.5.1/lib/python3.5/site-packages/pymysql/err.py", line 120, in raise_mysql_exception
    _check_mysql_exception(errinfo)
  File "/root/.pyenv/versions/3.5.1/lib/python3.5/site-packages/pymysql/err.py", line 112, in _check_mysql_exception
    raise errorclass(errno, errorvalue)
django.db.utils.ProgrammingError: (1146, "Table 'intest.intest_ints' doesn't exist")
[02/Sep/2016 10:07:59] "GET /admin/intest/ints/ HTTP/1.1" 500 234963
Performing system checks...

System check identified no issues (0 silenced).

You have unapplied migrations; your app may not work properly until they are applied.
Run 'python manage.py migrate' to apply them.
September 02, 2016 - 10:06:05
Django version 1.9.8, using settings 'myweb.settings'
Starting development server at http://0.0.0.0:8000/
Quit the server with CONTROL-C.
Internal Server Error: /admin/intest/ints/
Traceback (most recent call last):
  File "/root/.pyenv/versions/3.5.1/lib/python3.5/site-packages/django/db/backends/utils.py", line 64, in execute
    return self.cursor.execute(sql, params)
  File "/root/.pyenv/versions/3.5.1/lib/python3.5/site-packages/django/db/backends/mysql/base.py", line 112, in execute
    return self.cursor.execute(query, args)
  File "/root/.pyenv/versions/3.5.1/lib/python3.5/site-packages/pymysql/cursors.py", line 161, in execute
    result = self._query(query)
  File "/root/.pyenv/versions/3.5.1/lib/python3.5/site-packages/pymysql/cursors.py", line 317, in _query
    conn.query(q)
  File "/root/.pyenv/versions/3.5.1/lib/python3.5/site-packages/pymysql/connections.py", line 837, in query
    self._affected_rows = self._read_query_result(unbuffered=unbuffered)
  File "/root/.pyenv/versions/3.5.1/lib/python3.5/site-packages/pymysql/connections.py", line 1021, in _read_query_result
    result.read()
  File "/root/.pyenv/versions/3.5.1/lib/python3.5/site-packages/pymysql/connections.py", line 1304, in read
    first_packet = self.connection._read_packet()
  File "/root/.pyenv/versions/3.5.1/lib/python3.5/site-packages/pymysql/connections.py", line 983, in _read_packet
    packet.check_error()
  File "/root/.pyenv/versions/3.5.1/lib/python3.5/site-packages/pymysql/connections.py", line 395, in check_error
    err.raise_mysql_exception(self._data)
  File "/root/.pyenv/versions/3.5.1/lib/python3.5/site-packages/pymysql/err.py", line 120, in raise_mysql_exception
    _check_mysql_exception(errinfo)
  File "/root/.pyenv/versions/3.5.1/lib/python3.5/site-packages/pymysql/err.py", line 112, in _check_mysql_exception
    raise errorclass(errno, errorvalue)
pymysql.err.ProgrammingError: (1146, "Table 'intest.intest_ints' doesn't exist")

The above exception was the direct cause of the following exception:

Traceback (most recent call last):
  File "/root/.pyenv/versions/3.5.1/lib/python3.5/site-packages/django/core/handlers/base.py", line 149, in get_response
    response = self.process_exception_by_middleware(e, request)
  File "/root/.pyenv/versions/3.5.1/lib/python3.5/site-packages/django/core/handlers/base.py", line 147, in get_response
    response = wrapped_callback(request, *callback_args, **callback_kwargs)
  File "/root/.pyenv/versions/3.5.1/lib/python3.5/site-packages/django/contrib/admin/options.py", line 541, in wrapper
    return self.admin_site.admin_view(view)(*args, **kwargs)
  File "/root/.pyenv/versions/3.5.1/lib/python3.5/site-packages/django/utils/decorators.py", line 149, in _wrapped_view
    response = view_func(request, *args, **kwargs)
  File "/root/.pyenv/versions/3.5.1/lib/python3.5/site-packages/django/views/decorators/cache.py", line 57, in _wrapped_view_func
    response = view_func(request, *args, **kwargs)
  File "/root/.pyenv/versions/3.5.1/lib/python3.5/site-packages/django/contrib/admin/sites.py", line 244, in inner
    return view(request, *args, **kwargs)
  File "/root/.pyenv/versions/3.5.1/lib/python3.5/site-packages/django/utils/decorators.py", line 67, in _wrapper
    return bound_func(*args, **kwargs)
  File "/root/.pyenv/versions/3.5.1/lib/python3.5/site-packages/django/utils/decorators.py", line 149, in _wrapped_view
    response = view_func(request, *args, **kwargs)
  File "/root/.pyenv/versions/3.5.1/lib/python3.5/site-packages/django/utils/decorators.py", line 63, in bound_func
    return func.__get__(self, type(self))(*args2, **kwargs2)
  File "/root/.pyenv/versions/3.5.1/lib/python3.5/site-packages/django/contrib/admin/options.py", line 1470, in changelist_view
    self.list_max_show_all, self.list_editable, self)
  File "/root/.pyenv/versions/3.5.1/lib/python3.5/site-packages/django/contrib/admin/views/main.py", line 79, in __init__
    self.get_results(request)
  File "/root/.pyenv/versions/3.5.1/lib/python3.5/site-packages/django/contrib/admin/views/main.py", line 174, in get_results
    result_count = paginator.count
  File "/root/.pyenv/versions/3.5.1/lib/python3.5/site-packages/django/core/paginator.py", line 72, in _get_count
    self._count = self.object_list.count()
  File "/root/.pyenv/versions/3.5.1/lib/python3.5/site-packages/django/db/models/query.py", line 371, in count
    return self.query.get_count(using=self.db)
  File "/root/.pyenv/versions/3.5.1/lib/python3.5/site-packages/django/db/models/sql/query.py", line 483, in get_count
    number = obj.get_aggregation(using, ['__count'])['__count']
  File "/root/.pyenv/versions/3.5.1/lib/python3.5/site-packages/django/db/models/sql/query.py", line 464, in get_aggregation
    result = compiler.execute_sql(SINGLE)
  File "/root/.pyenv/versions/3.5.1/lib/python3.5/site-packages/django/db/models/sql/compiler.py", line 848, in execute_sql
    cursor.execute(sql, params)
  File "/root/.pyenv/versions/3.5.1/lib/python3.5/site-packages/django/db/backends/utils.py", line 79, in execute
    return super(CursorDebugWrapper, self).execute(sql, params)
  File "/root/.pyenv/versions/3.5.1/lib/python3.5/site-packages/django/db/backends/utils.py", line 64, in execute
    return self.cursor.execute(sql, params)
  File "/root/.pyenv/versions/3.5.1/lib/python3.5/site-packages/django/db/utils.py", line 95, in __exit__
    six.reraise(dj_exc_type, dj_exc_value, traceback)
  File "/root/.pyenv/versions/3.5.1/lib/python3.5/site-packages/django/utils/six.py", line 685, in reraise
    raise value.with_traceback(tb)
  File "/root/.pyenv/versions/3.5.1/lib/python3.5/site-packages/django/db/backends/utils.py", line 64, in execute
    return self.cursor.execute(sql, params)
  File "/root/.pyenv/versions/3.5.1/lib/python3.5/site-packages/django/db/backends/mysql/base.py", line 112, in execute
    return self.cursor.execute(query, args)
  File "/root/.pyenv/versions/3.5.1/lib/python3.5/site-packages/pymysql/cursors.py", line 161, in execute
    result = self._query(query)
  File "/root/.pyenv/versions/3.5.1/lib/python3.5/site-packages/pymysql/cursors.py", line 317, in _query
    conn.query(q)
  File "/root/.pyenv/versions/3.5.1/lib/python3.5/site-packages/pymysql/connections.py", line 837, in query
    self._affected_rows = self._read_query_result(unbuffered=unbuffered)
  File "/root/.pyenv/versions/3.5.1/lib/python3.5/site-packages/pymysql/connections.py", line 1021, in _read_query_result
    result.read()
  File "/root/.pyenv/versions/3.5.1/lib/python3.5/site-packages/pymysql/connections.py", line 1304, in read
    first_packet = self.connection._read_packet()
  File "/root/.pyenv/versions/3.5.1/lib/python3.5/site-packages/pymysql/connections.py", line 983, in _read_packet
    packet.check_error()
  File "/root/.pyenv/versions/3.5.1/lib/python3.5/site-packages/pymysql/connections.py", line 395, in check_error
    err.raise_mysql_exception(self._data)
  File "/root/.pyenv/versions/3.5.1/lib/python3.5/site-packages/pymysql/err.py", line 120, in raise_mysql_exception
    _check_mysql_exception(errinfo)
  File "/root/.pyenv/versions/3.5.1/lib/python3.5/site-packages/pymysql/err.py", line 112, in _check_mysql_exception
    raise errorclass(errno, errorvalue)
django.db.utils.ProgrammingError: (1146, "Table 'intest.intest_ints' doesn't exist")
[02/Sep/2016 10:10:40] "GET /admin/intest/ints/ HTTP/1.1" 500 234948
[02/Sep/2016 10:10:43] "GET /admin/ HTTP/1.1" 200 3414
Internal Server Error: /admin/intest/ints/
Traceback (most recent call last):
  File "/root/.pyenv/versions/3.5.1/lib/python3.5/site-packages/django/db/backends/utils.py", line 64, in execute
    return self.cursor.execute(sql, params)
  File "/root/.pyenv/versions/3.5.1/lib/python3.5/site-packages/django/db/backends/mysql/base.py", line 112, in execute
    return self.cursor.execute(query, args)
  File "/root/.pyenv/versions/3.5.1/lib/python3.5/site-packages/pymysql/cursors.py", line 161, in execute
    result = self._query(query)
  File "/root/.pyenv/versions/3.5.1/lib/python3.5/site-packages/pymysql/cursors.py", line 317, in _query
    conn.query(q)
  File "/root/.pyenv/versions/3.5.1/lib/python3.5/site-packages/pymysql/connections.py", line 837, in query
    self._affected_rows = self._read_query_result(unbuffered=unbuffered)
  File "/root/.pyenv/versions/3.5.1/lib/python3.5/site-packages/pymysql/connections.py", line 1021, in _read_query_result
    result.read()
  File "/root/.pyenv/versions/3.5.1/lib/python3.5/site-packages/pymysql/connections.py", line 1304, in read
    first_packet = self.connection._read_packet()
  File "/root/.pyenv/versions/3.5.1/lib/python3.5/site-packages/pymysql/connections.py", line 983, in _read_packet
    packet.check_error()
  File "/root/.pyenv/versions/3.5.1/lib/python3.5/site-packages/pymysql/connections.py", line 395, in check_error
    err.raise_mysql_exception(self._data)
  File "/root/.pyenv/versions/3.5.1/lib/python3.5/site-packages/pymysql/err.py", line 120, in raise_mysql_exception
    _check_mysql_exception(errinfo)
  File "/root/.pyenv/versions/3.5.1/lib/python3.5/site-packages/pymysql/err.py", line 112, in _check_mysql_exception
    raise errorclass(errno, errorvalue)
pymysql.err.ProgrammingError: (1146, "Table 'intest.intest_ints' doesn't exist")

The above exception was the direct cause of the following exception:

Traceback (most recent call last):
  File "/root/.pyenv/versions/3.5.1/lib/python3.5/site-packages/django/core/handlers/base.py", line 149, in get_response
    response = self.process_exception_by_middleware(e, request)
  File "/root/.pyenv/versions/3.5.1/lib/python3.5/site-packages/django/core/handlers/base.py", line 147, in get_response
    response = wrapped_callback(request, *callback_args, **callback_kwargs)
  File "/root/.pyenv/versions/3.5.1/lib/python3.5/site-packages/django/contrib/admin/options.py", line 541, in wrapper
    return self.admin_site.admin_view(view)(*args, **kwargs)
  File "/root/.pyenv/versions/3.5.1/lib/python3.5/site-packages/django/utils/decorators.py", line 149, in _wrapped_view
    response = view_func(request, *args, **kwargs)
  File "/root/.pyenv/versions/3.5.1/lib/python3.5/site-packages/django/views/decorators/cache.py", line 57, in _wrapped_view_func
    response = view_func(request, *args, **kwargs)
  File "/root/.pyenv/versions/3.5.1/lib/python3.5/site-packages/django/contrib/admin/sites.py", line 244, in inner
    return view(request, *args, **kwargs)
  File "/root/.pyenv/versions/3.5.1/lib/python3.5/site-packages/django/utils/decorators.py", line 67, in _wrapper
    return bound_func(*args, **kwargs)
  File "/root/.pyenv/versions/3.5.1/lib/python3.5/site-packages/django/utils/decorators.py", line 149, in _wrapped_view
    response = view_func(request, *args, **kwargs)
  File "/root/.pyenv/versions/3.5.1/lib/python3.5/site-packages/django/utils/decorators.py", line 63, in bound_func
    return func.__get__(self, type(self))(*args2, **kwargs2)
  File "/root/.pyenv/versions/3.5.1/lib/python3.5/site-packages/django/contrib/admin/options.py", line 1470, in changelist_view
    self.list_max_show_all, self.list_editable, self)
  File "/root/.pyenv/versions/3.5.1/lib/python3.5/site-packages/django/contrib/admin/views/main.py", line 79, in __init__
    self.get_results(request)
  File "/root/.pyenv/versions/3.5.1/lib/python3.5/site-packages/django/contrib/admin/views/main.py", line 174, in get_results
    result_count = paginator.count
  File "/root/.pyenv/versions/3.5.1/lib/python3.5/site-packages/django/core/paginator.py", line 72, in _get_count
    self._count = self.object_list.count()
  File "/root/.pyenv/versions/3.5.1/lib/python3.5/site-packages/django/db/models/query.py", line 371, in count
    return self.query.get_count(using=self.db)
  File "/root/.pyenv/versions/3.5.1/lib/python3.5/site-packages/django/db/models/sql/query.py", line 483, in get_count
    number = obj.get_aggregation(using, ['__count'])['__count']
  File "/root/.pyenv/versions/3.5.1/lib/python3.5/site-packages/django/db/models/sql/query.py", line 464, in get_aggregation
    result = compiler.execute_sql(SINGLE)
  File "/root/.pyenv/versions/3.5.1/lib/python3.5/site-packages/django/db/models/sql/compiler.py", line 848, in execute_sql
    cursor.execute(sql, params)
  File "/root/.pyenv/versions/3.5.1/lib/python3.5/site-packages/django/db/backends/utils.py", line 79, in execute
    return super(CursorDebugWrapper, self).execute(sql, params)
  File "/root/.pyenv/versions/3.5.1/lib/python3.5/site-packages/django/db/backends/utils.py", line 64, in execute
    return self.cursor.execute(sql, params)
  File "/root/.pyenv/versions/3.5.1/lib/python3.5/site-packages/django/db/utils.py", line 95, in __exit__
    six.reraise(dj_exc_type, dj_exc_value, traceback)
  File "/root/.pyenv/versions/3.5.1/lib/python3.5/site-packages/django/utils/six.py", line 685, in reraise
    raise value.with_traceback(tb)
  File "/root/.pyenv/versions/3.5.1/lib/python3.5/site-packages/django/db/backends/utils.py", line 64, in execute
    return self.cursor.execute(sql, params)
  File "/root/.pyenv/versions/3.5.1/lib/python3.5/site-packages/django/db/backends/mysql/base.py", line 112, in execute
    return self.cursor.execute(query, args)
  File "/root/.pyenv/versions/3.5.1/lib/python3.5/site-packages/pymysql/cursors.py", line 161, in execute
    result = self._query(query)
  File "/root/.pyenv/versions/3.5.1/lib/python3.5/site-packages/pymysql/cursors.py", line 317, in _query
    conn.query(q)
  File "/root/.pyenv/versions/3.5.1/lib/python3.5/site-packages/pymysql/connections.py", line 837, in query
    self._affected_rows = self._read_query_result(unbuffered=unbuffered)
  File "/root/.pyenv/versions/3.5.1/lib/python3.5/site-packages/pymysql/connections.py", line 1021, in _read_query_result
    result.read()
  File "/root/.pyenv/versions/3.5.1/lib/python3.5/site-packages/pymysql/connections.py", line 1304, in read
    first_packet = self.connection._read_packet()
  File "/root/.pyenv/versions/3.5.1/lib/python3.5/site-packages/pymysql/connections.py", line 983, in _read_packet
    packet.check_error()
  File "/root/.pyenv/versions/3.5.1/lib/python3.5/site-packages/pymysql/connections.py", line 395, in check_error
    err.raise_mysql_exception(self._data)
  File "/root/.pyenv/versions/3.5.1/lib/python3.5/site-packages/pymysql/err.py", line 120, in raise_mysql_exception
    _check_mysql_exception(errinfo)
  File "/root/.pyenv/versions/3.5.1/lib/python3.5/site-packages/pymysql/err.py", line 112, in _check_mysql_exception
    raise errorclass(errno, errorvalue)
django.db.utils.ProgrammingError: (1146, "Table 'intest.intest_ints' doesn't exist")
[02/Sep/2016 10:10:46] "GET /admin/intest/ints/ HTTP/1.1" 500 234965
[02/Sep/2016 10:12:24] "GET /tyreport/ HTTP/1.1" 302 0
[02/Sep/2016 10:12:24] "GET /tyblog/tyreport/ HTTP/1.1" 200 378734
[02/Sep/2016 10:20:15] "GET /admin/ HTTP/1.1" 302 0
[02/Sep/2016 10:20:15] "GET /admin/login/?next=/admin/ HTTP/1.1" 200 1683
[02/Sep/2016 10:20:16] "POST /admin/login/?next=/admin/ HTTP/1.1" 302 0
[02/Sep/2016 10:20:16] "GET /admin/ HTTP/1.1" 200 3414
Internal Server Error: /admin/intest/ints/
Traceback (most recent call last):
  File "/root/.pyenv/versions/3.5.1/lib/python3.5/site-packages/django/db/backends/utils.py", line 64, in execute
    return self.cursor.execute(sql, params)
  File "/root/.pyenv/versions/3.5.1/lib/python3.5/site-packages/django/db/backends/mysql/base.py", line 112, in execute
    return self.cursor.execute(query, args)
  File "/root/.pyenv/versions/3.5.1/lib/python3.5/site-packages/pymysql/cursors.py", line 161, in execute
    result = self._query(query)
  File "/root/.pyenv/versions/3.5.1/lib/python3.5/site-packages/pymysql/cursors.py", line 317, in _query
    conn.query(q)
  File "/root/.pyenv/versions/3.5.1/lib/python3.5/site-packages/pymysql/connections.py", line 837, in query
    self._affected_rows = self._read_query_result(unbuffered=unbuffered)
  File "/root/.pyenv/versions/3.5.1/lib/python3.5/site-packages/pymysql/connections.py", line 1021, in _read_query_result
    result.read()
  File "/root/.pyenv/versions/3.5.1/lib/python3.5/site-packages/pymysql/connections.py", line 1304, in read
    first_packet = self.connection._read_packet()
  File "/root/.pyenv/versions/3.5.1/lib/python3.5/site-packages/pymysql/connections.py", line 983, in _read_packet
    packet.check_error()
  File "/root/.pyenv/versions/3.5.1/lib/python3.5/site-packages/pymysql/connections.py", line 395, in check_error
    err.raise_mysql_exception(self._data)
  File "/root/.pyenv/versions/3.5.1/lib/python3.5/site-packages/pymysql/err.py", line 120, in raise_mysql_exception
    _check_mysql_exception(errinfo)
  File "/root/.pyenv/versions/3.5.1/lib/python3.5/site-packages/pymysql/err.py", line 112, in _check_mysql_exception
    raise errorclass(errno, errorvalue)
pymysql.err.ProgrammingError: (1146, "Table 'intest.intest_ints' doesn't exist")

The above exception was the direct cause of the following exception:

Traceback (most recent call last):
  File "/root/.pyenv/versions/3.5.1/lib/python3.5/site-packages/django/core/handlers/base.py", line 149, in get_response
    response = self.process_exception_by_middleware(e, request)
  File "/root/.pyenv/versions/3.5.1/lib/python3.5/site-packages/django/core/handlers/base.py", line 147, in get_response
    response = wrapped_callback(request, *callback_args, **callback_kwargs)
  File "/root/.pyenv/versions/3.5.1/lib/python3.5/site-packages/django/contrib/admin/options.py", line 541, in wrapper
    return self.admin_site.admin_view(view)(*args, **kwargs)
  File "/root/.pyenv/versions/3.5.1/lib/python3.5/site-packages/django/utils/decorators.py", line 149, in _wrapped_view
    response = view_func(request, *args, **kwargs)
  File "/root/.pyenv/versions/3.5.1/lib/python3.5/site-packages/django/views/decorators/cache.py", line 57, in _wrapped_view_func
    response = view_func(request, *args, **kwargs)
  File "/root/.pyenv/versions/3.5.1/lib/python3.5/site-packages/django/contrib/admin/sites.py", line 244, in inner
    return view(request, *args, **kwargs)
  File "/root/.pyenv/versions/3.5.1/lib/python3.5/site-packages/django/utils/decorators.py", line 67, in _wrapper
    return bound_func(*args, **kwargs)
  File "/root/.pyenv/versions/3.5.1/lib/python3.5/site-packages/django/utils/decorators.py", line 149, in _wrapped_view
    response = view_func(request, *args, **kwargs)
  File "/root/.pyenv/versions/3.5.1/lib/python3.5/site-packages/django/utils/decorators.py", line 63, in bound_func
    return func.__get__(self, type(self))(*args2, **kwargs2)
  File "/root/.pyenv/versions/3.5.1/lib/python3.5/site-packages/django/contrib/admin/options.py", line 1470, in changelist_view
    self.list_max_show_all, self.list_editable, self)
  File "/root/.pyenv/versions/3.5.1/lib/python3.5/site-packages/django/contrib/admin/views/main.py", line 79, in __init__
    self.get_results(request)
  File "/root/.pyenv/versions/3.5.1/lib/python3.5/site-packages/django/contrib/admin/views/main.py", line 174, in get_results
    result_count = paginator.count
  File "/root/.pyenv/versions/3.5.1/lib/python3.5/site-packages/django/core/paginator.py", line 72, in _get_count
    self._count = self.object_list.count()
  File "/root/.pyenv/versions/3.5.1/lib/python3.5/site-packages/django/db/models/query.py", line 371, in count
    return self.query.get_count(using=self.db)
  File "/root/.pyenv/versions/3.5.1/lib/python3.5/site-packages/django/db/models/sql/query.py", line 483, in get_count
    number = obj.get_aggregation(using, ['__count'])['__count']
  File "/root/.pyenv/versions/3.5.1/lib/python3.5/site-packages/django/db/models/sql/query.py", line 464, in get_aggregation
    result = compiler.execute_sql(SINGLE)
  File "/root/.pyenv/versions/3.5.1/lib/python3.5/site-packages/django/db/models/sql/compiler.py", line 848, in execute_sql
    cursor.execute(sql, params)
  File "/root/.pyenv/versions/3.5.1/lib/python3.5/site-packages/django/db/backends/utils.py", line 79, in execute
    return super(CursorDebugWrapper, self).execute(sql, params)
  File "/root/.pyenv/versions/3.5.1/lib/python3.5/site-packages/django/db/backends/utils.py", line 64, in execute
    return self.cursor.execute(sql, params)
  File "/root/.pyenv/versions/3.5.1/lib/python3.5/site-packages/django/db/utils.py", line 95, in __exit__
    six.reraise(dj_exc_type, dj_exc_value, traceback)
  File "/root/.pyenv/versions/3.5.1/lib/python3.5/site-packages/django/utils/six.py", line 685, in reraise
    raise value.with_traceback(tb)
  File "/root/.pyenv/versions/3.5.1/lib/python3.5/site-packages/django/db/backends/utils.py", line 64, in execute
    return self.cursor.execute(sql, params)
  File "/root/.pyenv/versions/3.5.1/lib/python3.5/site-packages/django/db/backends/mysql/base.py", line 112, in execute
    return self.cursor.execute(query, args)
  File "/root/.pyenv/versions/3.5.1/lib/python3.5/site-packages/pymysql/cursors.py", line 161, in execute
    result = self._query(query)
  File "/root/.pyenv/versions/3.5.1/lib/python3.5/site-packages/pymysql/cursors.py", line 317, in _query
    conn.query(q)
  File "/root/.pyenv/versions/3.5.1/lib/python3.5/site-packages/pymysql/connections.py", line 837, in query
    self._affected_rows = self._read_query_result(unbuffered=unbuffered)
  File "/root/.pyenv/versions/3.5.1/lib/python3.5/site-packages/pymysql/connections.py", line 1021, in _read_query_result
    result.read()
  File "/root/.pyenv/versions/3.5.1/lib/python3.5/site-packages/pymysql/connections.py", line 1304, in read
    first_packet = self.connection._read_packet()
  File "/root/.pyenv/versions/3.5.1/lib/python3.5/site-packages/pymysql/connections.py", line 983, in _read_packet
    packet.check_error()
  File "/root/.pyenv/versions/3.5.1/lib/python3.5/site-packages/pymysql/connections.py", line 395, in check_error
    err.raise_mysql_exception(self._data)
  File "/root/.pyenv/versions/3.5.1/lib/python3.5/site-packages/pymysql/err.py", line 120, in raise_mysql_exception
    _check_mysql_exception(errinfo)
  File "/root/.pyenv/versions/3.5.1/lib/python3.5/site-packages/pymysql/err.py", line 112, in _check_mysql_exception
    raise errorclass(errno, errorvalue)
django.db.utils.ProgrammingError: (1146, "Table 'intest.intest_ints' doesn't exist")
